Workbook

Sheet INSTRUCCIONES
A1: Plantilla oficial de compras por lote — La Abundancia v1.39.1
A3: Uso principal | B3: Editar el Excel oficial, llenar cantidad, medida y total de compra; luego subir el archivo .xlsx en Calculadora > Cálculo de Precios por Lote.
A4: Qué sí editar | B4: DATOS_LOTE: número, fecha y proveedor. FACTURA_LIMPIA: columnas CANT., MEDIDA y TOTAL de cada producto.
A5: Qué no editar | B5: No cambiar nombres de productos, filas, columnas, hojas técnicas, claves ni fórmulas. La app usa esas posiciones para conectar con los IDs.
A6: Formato recomendado | B6: Subir este archivo .xlsx directamente. La hoja IMPORT_APP queda como respaldo técnico, pero la app puede leer FACTURA_LIMPIA por posiciones fijas.
A7: GitHub | B7: Buena idea subir este archivo a GitHub como plantilla oficial. Usa un nombre estable para que la app pueda descargarlo o abrirlo desde un enlace fijo.
A8: Seguridad | B8: La importación en la app debe quedar en borrador. Nada se actualiza en productos/inventario hasta revisar y confirmar con PIN.
D10: Flujo recomendado
A11: Unidad permitida | B11: Uso | D11: 1. Descarga este Excel oficial desde GitHub o desde la app.
A12: KG / KL / KILO | B12: Compra por kilo | D12: 2. Llena DATOS_LOTE.
A13: UND / UNIDAD | B13: Compra por unidad | D13: 3. En FACTURA_LIMPIA llena solo CANT., MEDIDA y TOTAL.
A14: CJ / CAJA | B14: Caja completa | D14: 4. Sube el .xlsx a la app.
A15: BT / BULTO | B15: Bulto completo | D15: 5. Revisa productos listos, productos manuales y productos nuevos.
A16: MTA / MATA | B16: Mata completa | D16: 6. Confirma con PIN para actualizar costos, precios e inventario.
A17: BJA / BANDEJA | B17: Bandeja completa
A18: PAQ / PAQUETE | B18: Paquete
A19: ARROBA | B19: Arroba

Sheet DATOS_LOTE
A1: Datos del lote / factura
A3: Campo | B3: Valor
A4: Número factura/lote
A5: Fecha lote
A6: Proveedor
A7: Responsable
A8: Observaciones
A9: Versión plantilla | B9: 1.39.1
A11: Regla | B11: Descripción
A12: Obligatorio | B12: La app debe pedir fecha si B5 está vacío.
A13: No cambiar | B13: El nombre de las hojas debe conservarse.
A14: GitHub | B14: Subir este archivo como asset de Release o archivo estable del repositorio.
A15: App | B15: La app debe leer FACTURA_LIMPIA y/o IMPORT_APP.

Sheet FACTURA_LIMPIA
A1: CANT. | B1: MEDIDA | C1: PRODUCTO | D1: TOTAL | F1: CANT. | G1: MEDIDA | H1: PRODUCTO | I1: TOTAL
C2: Acelga | H2: Maíz por Arroba
C3: Aguacate | H3: Maíz Entero
C4: Ahuyamín | H4: Maíz Partido
C5: Ají | H5: Mandarina
C6: Ajo Criollo | H6: Mango
C7: Ajo Blanco | H7: Manzana Verde
C8: Ajo Pelado | H8: Manzana Roja
C9: Apio España | H9: Manzana Royale
C10: Arándanos | H10: Maracuyá
C11: Arveja | H11: Melón
C12: Arracacha | H12: Mazorca Bandeja
C13: Banano | H13: Mora
... C46: Limón Mandarino | H46: Zumo Limón Pequeño
C47: Lulo
H49: TOTAL ESTA FACTURA $ | I49: =SUM(D2:D47)+SUM(I2:I46) -> 0
A50: INSTRUCCIÓN: | B50: Llena solo CANT., MEDIDA y TOTAL. No cambies nombres de productos ni orden de filas.
A51: UNIDADES: | B51: KG/KL/KILO, UND/UNIDAD, CJ/CAJA, BT/BULTO, MTA/MATA, BJA/BANDEJA, PAQ/PAQUETE, ARROBA.
A52: APP: | B52: La app ignorará filas sin cantidad o sin total de compra.

Sheet IMPORT_APP
A1: formato | B1: version | C1: numeroFactura | D1: fechaLote | E1: seccion | F1: filaExcel | G1: productoPlantilla | H1: productoClave | I1: cantidad | J1: medida | K1: totalCompra | L1: observacion | N1: Nota técnica
A2: LAABUNDANCIA_LOTE | B2: 1 | C2: =IF(DATOS_LOTE!$B$4="","",DATOS_LOTE!$B$4) | D2: =IF(DATOS_LOTE!$B$5="","",DATOS_LOTE!$B$5) | E2: IZQUIERDA | F2: 2 | G2: Acelga | H2: acelga | I2: =IF(FACTURA_LIMPIA!A2="","",FACTURA_LIMPIA!A2) | J2: =IF(FACTURA_LIMPIA!B2="","",FACTURA_LIMPIA!B2) | K2: =IF(FACTURA_LIMPIA!D2="","",FACTURA_LIMPIA!D2) | N2: Esta hoja se llena automáticamente desde FACTURA_LIMPIA. No editar. La app debe ignorar filas vacías.
A3: LAABUNDANCIA_LOTE | B3: 1 | C3: =IF(DATOS_LOTE!$B$4="","",DATOS_LOTE!$B$4) | D3: =IF(DATOS_LOTE!$B$5="","",DATOS_LOTE!$B$5) | E3: IZQUIERDA | F3: 3 | G3: Aguacate | H3: aguacate | I3: =IF(FACTURA_LIMPIA!A3="","",FACTURA_LIMPIA!A3) | J3: =IF(FACTURA_LIMPIA!B3="","",FACTURA_LIMPIA!B3) | K3: =IF(FACTURA_LIMPIA!D3="","",FACTURA_LIMPIA!D3)
A4: LAABUNDANCIA_LOTE | B4: 1 | C4: =IF(DATOS_LOTE!$B$4="","",DATOS_LOTE!$B$4) | D4: =IF(DATOS_LOTE!$B$5="","",DATOS_LOTE!$B$5) | E4: IZQUIERDA | F4: 4 | G4: Ahuyamín | H4: ahuyamin | I4: =IF(FACTURA_LIMPIA!A4="","",FACTURA_LIMPIA!A4) | J4: =IF(FACTURA_LIMPIA!B4="","",FACTURA_LIMPIA!B4) | K4: =IF(FACTURA_LIMPIA!D4="","",FACTURA_LIMPIA!D4)
A5: LAABUNDANCIA_LOTE | B5: 1 | C5: =IF(DATOS_LOTE!$B$4="","",DATOS_LOTE!$B$4) | D5: =IF(DATOS_LOTE!$B$5="","",DATOS_LOTE!$B$5) | E5: IZQUIERDA | F5: 5 | G5: Ají | H5: aji_manual | I5: =IF(FACTURA_LIMPIA!A5="","",FACTURA_LIMPIA!A5) | J5: =IF(FACTURA_LIMPIA!B5="","",FACTURA_LIMPIA!B5) | K5: =IF(FACTURA_LIMPIA!D5="","",FACTURA_LIMPIA!D5)
A6: LAABUNDANCIA_LOTE | B6: 1 | C6: =IF(DATOS_LOTE!$B$4="","",DATOS_LOTE!$B$4) | D6: =IF(DATOS_LOTE!$B$5="","",DATOS_LOTE!$B$5) | E6: IZQUIERDA | F6: 6 | G6: Ajo Criollo | H6: ajo_criollo_manojo | I6: =IF(FACTURA_LIMPIA!A6="","",FACTURA_LIMPIA!A6) | J6: =IF(FACTURA_LIMPIA!B6="","",FACTURA_LIMPIA!B6) | K6: =IF(FACTURA_LIMPIA!D6="","",FACTURA_LIMPIA!D6)
A7: LAABUNDANCIA_LOTE | B7: 1 | C7: =IF(DATOS_LOTE!$B$4="","",DATOS_LOTE!$B$4) | D7: =IF(DATOS_LOTE!$B$5="","",DATOS_LOTE!$B$5) | E7: IZQUIERDA | F7: 7 | G7: Ajo Blanco | H7: ajo_blanco_paquete | I7: =IF(FACTURA_LIMPIA!A7="","",FACTURA_LIMPIA!A7) | J7: =IF(FACTURA_LIMPIA!B7="","",FACTURA_LIMPIA!B7) | K7: =IF(FACTURA_LIMPIA!D7="","",FACTURA_LIMPIA!D7)
A8: LAABUNDANCIA_LOTE | B8: 1 | C8: =IF(DATOS_LOTE!$B$4="","",DATOS_LOTE!$B$4) | D8: =IF(DATOS_LOTE!$B$5="","",DATOS_LOTE!$B$5) | E8: IZQUIERDA | F8: 8 | G8: Ajo Pelado | H8: ajo_pelado_base | I8: =IF(FACTURA_LIMPIA!A8="","",FACTURA_LIMPIA!A8) | J8: =IF(FACTURA_LIMPIA!B8="","",FACTURA_LIMPIA!B8) | K8: =IF(FACTURA_LIMPIA!D8="","",FACTURA_LIMPIA!D8)
A9: LAABUNDANCIA_LOTE | B9: 1 | C9: =IF(DATOS_LOTE!$B$4="","",DATOS_LOTE!$B$4) | D9: =IF(DATOS_LOTE!$B$5="","",DATOS_LOTE!$B$5) | E9: IZQUIERDA | F9: 9 | G9: Apio España | H9: apio_espana | I9: =IF(FACTURA_LIMPIA!A9="","",FACTURA_LIMPIA!A9) | J9: =IF(FACTURA_LIMPIA!B9="","",FACTURA_LIMPIA!B9) | K9: =IF(FACTURA_LIMPIA!D9="","",FACTURA_LIMPIA!D9)
A10: LAABUNDANCIA_LOTE | B10: 1 | C10: =IF(DATOS_LOTE!$B$4="","",DATOS_LOTE!$B$4) | D10: =IF(DATOS_LOTE!$B$5="","",DATOS_LOTE!$B$5) | E10: IZQUIERDA | F10: 10 | G10: Arándanos | H10: arandanos | I10: =IF(FACTURA_LIMPIA!A10="","",FACTURA_LIMPIA!A10) | J10: =IF(FACTURA_LIMPIA!B10="","",FACTURA_LIMPIA!B10) | K10: =IF(FACTURA_LIMPIA!D10="","",FACTURA_LIMPIA!D10)
A11: LAABUNDANCIA_LOTE | B11: 1 | C11: =IF(DATOS_LOTE!$B$4="","",DATOS_LOTE!$B$4) | D11: =IF(DATOS_LOTE!$B$5="","",DATOS_LOTE!$B$5) | E11: IZQUIERDA | F11: 11 | G11: Arveja | H11: arveja_con_cascara | I11: =IF(FACTURA_LIMPIA!A11="","",FACTURA_LIMPIA!A11) | J11: =IF(FACTURA_LIMPIA!B11="","",FACTURA_LIMPIA!B11) | K11: =IF(FACTURA_LIMPIA!D11="","",FACTURA_LIMPIA!D11)
A12: LAABUNDANCIA_LOTE | B12: 1 | C12: =IF(DATOS_LOTE!$B$4="","",DATOS_LOTE!$B$4) | D12: =IF(DATOS_LOTE!$B$5="","",DATOS_LOTE!$B$5) | E12: IZQUIERDA | F12: 12 | G12: Arracacha | H12: arracacha | I12: =IF(FACTURA_LIMPIA!A12="","",FACTURA_LIMPIA!A12) | J12: =IF(FACTURA_LIMPIA!B12="","",FACTURA_LIMPIA!B12) | K12: =IF(FACTURA_LIMPIA!D12="","",FACTURA_LIMPIA!D12)
A13: LAABUNDANCIA_LOTE | B13: 1 | C13: =IF(DATOS_LOTE!$B$4="","",DATOS_LOTE!$B$4) | D13: =IF(DATOS_LOTE!$B$5="","",DATOS_LOTE!$B$5) | E13: IZQUIERDA | F13: 13 | G13: Banano | H13: banano | I13: =IF(FACTURA_LIMPIA!A13="","",FACTURA_LIMPIA!A13) | J13: =IF(FACTURA_LIMPIA!B13="","",FACTURA_LIMPIA!B13) | K13: =IF(FACTURA_LIMPIA!D13="","",FACTURA_LIMPIA!D13)
A14: LAABUNDANCIA_LOTE | B14: 1 | C14: =IF(DATOS_LOTE!$B$4="","",DATOS_LOTE!$B$4) | D14: =IF(DATOS_LOTE!$B$5="","",DATOS_LOTE!$B$5) | E14: IZQUIERDA | F14: 14 | G14: Berenjena | H14: berenjena | I14: =IF(FACTURA_LIMPIA!A14="","",FACTURA_LIMPIA!A14) | J14: =IF(FACTURA_LIMPIA!B14="","",FACTURA_LIMPIA!B14) | K14: =IF(FACTURA_LIMPIA!D14="","",FACTURA_LIMPIA!D14)
... A47: LAABUNDANCIA_LOTE | B47: 1 | C47: =IF(DATOS_LOTE!$B$4="","",DATOS_LOTE!$B$4) | D47: =IF(DATOS_LOTE!$B$5="","",DATOS_LOTE!$B$5) | E47: IZQUIERDA | F47: 47 | G47: Lulo | H47: lulo_fresco | I47: =IF(FACTURA_LIMPIA!A47="","",FACTURA_LIMPIA!A47) | J47: =IF(FACTURA_LIMPIA!B47="","",FACTURA_LIMPIA!B47) | K47: =IF(FACTURA_LIMPIA!D47="","",FACTURA_LIMPIA!D47)
A48: LAABUNDANCIA_LOTE | B48: 1 | C48: =IF(DATOS_LOTE!$B$4="","",DATOS_LOTE!$B$4) | D48: =IF(DATOS_LOTE!$B$5="","",DATOS_LOTE!$B$5) | E48: DERECHA | F48: 2 | G48: Maíz por Arroba | H48: maiz_por_arroba | I48: =IF(FACTURA_LIMPIA!F2="","",FACTURA_LIMPIA!F2) | J48: =IF(FACTURA_LIMPIA!G2="","",FACTURA_LIMPIA!G2) | K48: =IF(FACTURA_LIMPIA!I2="","",FACTURA_LIMPIA!I2)
A49: LAABUNDANCIA_LOTE | B49: 1 | C49: =IF(DATOS_LOTE!$B$4="","",DATOS_LOTE!$B$4) | D49: =IF(DATOS_LOTE!$B$5="","",DATOS_LOTE!$B$5) | E49: DERECHA | F49: 3 | G49: Maíz Entero | H49: maiz_entero | I49: =IF(FACTURA_LIMPIA!F3="","",FACTURA_LIMPIA!F3) | J49: =IF(FACTURA_LIMPIA!G3="","",FACTURA_LIMPIA!G3) | K49: =IF(FACTURA_LIMPIA!I3="","",FACTURA_LIMPIA!I3)
A50: LAABUNDANCIA_LOTE | B50: 1 | C50: =IF(DATOS_LOTE!$B$4="","",DATOS_LOTE!$B$4) | D50: =IF(DATOS_LOTE!$B$5="","",DATOS_LOTE!$B$5) | E50: DERECHA | F50: 4 | G50: Maíz Partido | H50: maiz_partido | I50: =IF(FACTURA_LIMPIA!F4="","",FACTURA_LIMPIA!F4) | J50: =IF(FACTURA_LIMPIA!G4="","",FACTURA_LIMPIA!G4) | K50: =IF(FACTURA_LIMPIA!I4="","",FACTURA_LIMPIA!I4)
A51: LAABUNDANCIA_LOTE | B51: 1 | C51: =IF(DATOS_LOTE!$B$4="","",DATOS_LOTE!$B$4) | D51: =IF(DATOS_LOTE!$B$5="","",DATOS_LOTE!$B$5) | E51: DERECHA | F51: 5 | G51: Mandarina | H51: mandarina | I51: =IF(FACTURA_LIMPIA!F5="","",FACTURA_LIMPIA!F5) | J51: =IF(FACTURA_LIMPIA!G5="","",FACTURA_LIMPIA!G5) | K51: =IF(FACTURA_LIMPIA!I5="","",FACTURA_LIMPIA!I5)
A52: LAABUNDANCIA_LOTE | B52: 1 | C52: =IF(DATOS_LOTE!$B$4="","",DATOS_LOTE!$B$4) | D52: =IF(DATOS_LOTE!$B$5="","",DATOS_LOTE!$B$5) | E52: DERECHA | F52: 6 | G52: Mango | H52: mango | I52: =IF(FACTURA_LIMPIA!F6="","",FACTURA_LIMPIA!F6) | J52: =IF(FACTURA_LIMPIA!G6="","",FACTURA_LIMPIA!G6) | K52: =IF(FACTURA_LIMPIA!I6="","",FACTURA_LIMPIA!I6)
A53: LAABUNDANCIA_LOTE | B53: 1 | C53: =IF(DATOS_LOTE!$B$4="","",DATOS_LOTE!$B$4) | D53: =IF(DATOS_LOTE!$B$5="","",DATOS_LOTE!$B$5) | E53: DERECHA | F53: 7 | G53: Manzana Verde | H53: manzana_verde | I53: =IF(FACTURA_LIMPIA!F7="","",FACTURA_LIMPIA!F7) | J53: =IF(FACTURA_LIMPIA!G7="","",FACTURA_LIMPIA!G7) | K53: =IF(FACTURA_LIMPIA!I7="","",FACTURA_LIMPIA!I7)
A54: LAABUNDANCIA_LOTE | B54: 1 | C54: =IF(DATOS_LOTE!$B$4="","",DATOS_LOTE!$B$4) | D54: =IF(DATOS_LOTE!$B$5="","",DATOS_LOTE!$B$5) | E54: DERECHA | F54: 8 | G54: Manzana Roja | H54: manzana_roja | I54: =IF(FACTURA_LIMPIA!F8="","",FACTURA_LIMPIA!F8) | J54: =IF(FACTURA_LIMPIA!G8="","",FACTURA_LIMPIA!G8) | K54: =IF(FACTURA_LIMPIA!I8="","",FACTURA_LIMPIA!I8)
A55: LAABUNDANCIA_LOTE | B55: 1 | C55: =IF(DATOS_LOTE!$B$4="","",DATOS_LOTE!$B$4) | D55: =IF(DATOS_LOTE!$B$5="","",DATOS_LOTE!$B$5) | E55: DERECHA | F55: 9 | G55: Manzana Royale | H55: manzana_royale | I55: =IF(FACTURA_LIMPIA!F9="","",FACTURA_LIMPIA!F9) | J55: =IF(FACTURA_LIMPIA!G9="","",FACTURA_LIMPIA!G9) | K55: =IF(FACTURA_LIMPIA!I9="","",FACTURA_LIMPIA!I9)
A56: LAABUNDANCIA_LOTE | B56: 1 | C56: =IF(DATOS_LOTE!$B$4="","",DATOS_LOTE!$B$4) | D56: =IF(DATOS_LOTE!$B$5="","",DATOS_LOTE!$B$5) | E56: DERECHA | F56: 10 | G56: Maracuyá | H56: maracuya | I56: =IF(FACTURA_LIMPIA!F10="","",FACTURA_LIMPIA!F10) | J56: =IF(FACTURA_LIMPIA!G10="","",FACTURA_LIMPIA!G10) | K56: =IF(FACTURA_LIMPIA!I10="","",FACTURA_LIMPIA!I10)
A57: LAABUNDANCIA_LOTE | B57: 1 | C57: =IF(DATOS_LOTE!$B$4="","",DATOS_LOTE!$B$4) | D57: =IF(DATOS_LOTE!$B$5="","",DATOS_LOTE!$B$5) | E57: DERECHA | F57: 11 | G57: Melón | H57: melon | I57: =IF(FACTURA_LIMPIA!F11="","",FACTURA_LIMPIA!F11) | J57: =IF(FACTURA_LIMPIA!G11="","",FACTURA_LIMPIA!G11) | K57: =IF(FACTURA_LIMPIA!I11="","",FACTURA_LIMPIA!I11)
A58: LAABUNDANCIA_LOTE | B58: 1 | C58: =IF(DATOS_LOTE!$B$4="","",DATOS_LOTE!$B$4) | D58: =IF(DATOS_LOTE!$B$5="","",DATOS_LOTE!$B$5) | E58: DERECHA | F58: 12 | G58: Mazorca Bandeja | H58: mazorca_bandeja | I58: =IF(FACTURA_LIMPIA!F12="","",FACTURA_LIMPIA!F12) | J58: =IF(FACTURA_LIMPIA!G12="","",FACTURA_LIMPIA!G12) | K58: =IF(FACTURA_LIMPIA!I12="","",FACTURA_LIMPIA!I12)
A59: LAABUNDANCIA_LOTE | B59: 1 | C59: =IF(DATOS_LOTE!$B$4="","",DATOS_LOTE!$B$4) | D59: =IF(DATOS_LOTE!$B$5="","",DATOS_LOTE!$B$5) | E59: DERECHA | F59: 13 | G59: Mora | H59: mora_fresca | I59: =IF(FACTURA_LIMPIA!F13="","",FACTURA_LIMPIA!F13) | J59: =IF(FACTURA_LIMPIA!G13="","",FACTURA_LIMPIA!G13) | K59: =IF(FACTURA_LIMPIA!I13="","",FACTURA_LIMPIA!I13)
... A92: LAABUNDANCIA_LOTE | B92: 1 | C92: =IF(DATOS_LOTE!$B$4="","",DATOS_LOTE!$B$4) | D92: =IF(DATOS_LOTE!$B$5="","",DATOS_LOTE!$B$5) | E92: DERECHA | F92: 46 | G92: Zumo Limón Pequeño | H92: zumo_limon_pequeno | I92: =IF(FACTURA_LIMPIA!F46="","",FACTURA_LIMPIA!F46) | J92: =IF(FACTURA_LIMPIA!G46="","",FACTURA_LIMPIA!G46) | K92: =IF(FACTURA_LIMPIA!I46="","",FACTURA_LIMPIA!I46)

Sheet MAPEO_APP
A1: seccion | B1: filaExcel | C1: productoPlantilla | D1: productoClave | E1: estado | F1: productoAppPrincipal | G1: appProductId | H1: productosVinculados | I1: regla | J1: margenObjetivo | K1: unidadCompraSugerida | L1: unidadVentaSugerida | M1: nota
A2: IZQUIERDA | B2: 2 | C2: Acelga | D2: acelga | E2: CONECTADO_CON_CORRECCION | F2: Aceiga | G2: d9399b15-e43d-49c0-9c40-b9c471a720a5 | I2: DIRECTO_KILO | J2: 60 | K2: KILO | L2: KILO | M2: Compra kilo, vende kilo. Margen mínimo 60%.
A3: IZQUIERDA | B3: 3 | C3: Aguacate | D3: aguacate | E3: CONECTADO | F3: Aguacate | G3: e222575f-dc11-4222-b1fb-6aa81db8e667 | I3: DIRECTO_KILO | J3: 45 | K3: KILO | L3: KILO | M3: Compra kilo, vende kilo. Margen recomendado 40-45%.
A4: IZQUIERDA | B4: 4 | C4: Ahuyamín | D4: ahuyamin | E4: CONECTADO | F4: Ahuyamin | G4: 0b89bf7a-bd60-46f7-975c-9133334e8a61 | I4: DIRECTO_KILO | J4: 35 | K4: KILO | L4: KILO | M4: Compra kilo, vende kilo. Margen 35%.
A5: IZQUIERDA | B5: 5 | C5: Ají | D5: aji_manual | E5: MANUAL | F5: Selección manual | I5: MANUAL | J5: 60 | K5: KILO | L5: KILO | M5: Manejo manual. No actualizar automáticamente.
A6: IZQUIERDA | B6: 6 | C6: Ajo Criollo | D6: ajo_criollo_manojo | E6: CREAR_EN_APP | I6: MATA_A_UNIDAD | J6: 45 | K6: UNIDAD | L6: UNIDAD | M6: 1 mata = 10 manojos. Precio manojo = costo mata / 10 × 1,45.
A7: IZQUIERDA | B7: 7 | C7: Ajo Blanco | D7: ajo_blanco_paquete | E7: CONECTADO | F7: Ajo Blanco | G7: 55743b25-0997-4e63-8b29-ec2e78ef77e4 | I7: KILO_A_PAQUETE_ESPECIAL | J7: 100 | K7: KILO | L7: KILO | M7: De 2 kg salen 21 paquetes de 3 cabezas. Precio = costo paquete × 2.
A8: IZQUIERDA | B8: 8 | C8: Ajo Pelado | D8: ajo_pelado_base | E8: MULTI_FORMULA | H8: Ajo Pelado Bolsa Grande, Ajo Pelado Bolsa Pequeña | I8: MULTI_FORMULA | J8: 45 | K8: KILO | L8: KILO | M8: Kilo base: 150g margen 45%; 75g margen 60%.
A9: IZQUIERDA | B9: 9 | C9: Apio España | D9: apio_espana | E9: CREAR_EN_APP | I9: MATA_A_KILO_ESPECIAL | J9: 70 | K9: MATA | L9: KILO | M9: Vender $3.000/kg si mata <= $3.970 y pesa mínimo 2,25kg; si no, costoKg × 1,70.
A10: IZQUIERDA | B10: 10 | C10: Arándanos | D10: arandanos | E10: CREAR_EN_APP | I10: SIN_REGLA | J10: 50 | K10: KILO | L10: KILO | M10: Sin regla específica. Revisar manualmente.
A11: IZQUIERDA | B11: 11 | C11: Arveja | D11: arveja_con_cascara | E11: MULTI_FORMULA | F11: Arveja | G11: 513b67c9-316d-47cd-9597-73ebb039f6fe | H11: Arveja, Arveja Desgranada, Arveja Paquete 150g, Arveja Paquete 260g | I11: MULTI_FORMULA | J11: 35 | K11: KILO | L11: KILO | M11: 3 kg con cáscara = 1 kg desgranada. Paquetes 150g y 270g según fórmula.
A12: IZQUIERDA | B12: 12 | C12: Arracacha | D12: arracacha | E12: CONECTADO | F12: Arracacha | G12: 78fdedcf-83c5-4eb0-a473-15f6420a61cc | I12: DIRECTO_KILO | J12: 35 | K12: KILO | L12: KILO | M12: Compra kilo, vende kilo. Margen 35%.
A13: IZQUIERDA | B13: 13 | C13: Banano | D13: banano | E13: CONECTADO | F13: Banano | G13: 9ed94e62-a9b8-4e45-a824-f5644905d1ff | I13: CAJA_A_KILO | J13: 40 | K13: CAJA | L13: KILO | M13: Caja default 18,5 kg. Vende kilo.
A14: IZQUIERDA | B14: 14 | C14: Berenjena | D14: berenjena | E14: CREAR_EN_APP | I14: SIN_REGLA | J14: 50 | K14: KILO | L14: KILO | M14: Sin regla específica. Revisar manualmente.
A15: IZQUIERDA | B15: 15 | C15: Brócoli | D15: brocoli | E15: CONECTADO | F15: Brócoli | G15: 73ada553-f806-41ea-9266-7722a7e72862 | I15: DIRECTO_UNIDAD | J15: 50 | K15: UNIDAD | L15: UNIDAD | M15: Compra unidad, vende unidad. Margen 50%.
A16: IZQUIERDA | B16: 16 | C16: Calabaza | D16: calabaza | E16: CREAR_EN_APP | I16: SIN_REGLA | J16: 50 | K16: KILO | L16: KILO | M16: Sin regla específica. Revisar manualmente.
A17: IZQUIERDA | B17: 17 | C17: Calabacín | D17: calabacin | E17: CREAR_EN_APP | I17: SIN_REGLA | J17: 50 | K17: KILO | L17: KILO | M17: Sin regla específica. Revisar manualmente.
A18: IZQUIERDA | B18: 18 | C18: Ceb. Cabezona Blanca | D18: cebolla_cabezona_blanca | E18: CREAR_EN_APP | I18: BULTO_A_KILO | J18: 60 | K18: BULTO | L18: KILO | M18: Bulto default 50 kg o kilo. Margen recomendado 50-60%.
A19: IZQUIERDA | B19: 19 | C19: Ceb. Cabezona Roja | D19: cebolla_cabezona_roja | E19: CREAR_EN_APP | I19: DIRECTO_KILO | J19: 35 | K19: KILO | L19: KILO | M19: Compra kilo, vende kilo. Margen 35%.
A20: IZQUIERDA | B20: 20 | C20: Ceb. Larga | D20: cebolla_larga | E20: CREAR_EN_APP | I20: MATA_A_KILO | J20: 60 | K20: MATA | L20: KILO | M20: Mata default 25 kg. Vende kilo. Margen recomendado 50-60%.
A21: IZQUIERDA | B21: 21 | C21: Ceb. Puerro | D21: ceb_puerro | E21: CREAR_EN_APP | I21: SIN_REGLA | J21: 50 | K21: KILO | L21: KILO | M21: Sin regla específica. Revisar manualmente.
A22: IZQUIERDA | B22: 22 | C22: Cilantro | D22: cilantro | E22: MULTI_FORMULA | F22: Cilantro | G22: 1b6efa36-f8ca-42e9-809f-3ac2ecf36363 | H22: Cilantro, Cilantro por Unidad | I22: MULTI_FORMULA | J22: 119 | K22: KILO | L22: KILO | M22: Paquete 65g, precio base $1.000, objetivo 119%.
A23: IZQUIERDA | B23: 23 | C23: Ciruela | D23: ciruela | E23: CONECTADO | F23: Ciruela | G23: d150c4a0-a97b-4254-9a06-995ba7a40fdf | I23: DIRECTO_BANDEJA | J23: 50 | K23: BANDEJA | L23: BANDEJA | M23: Compra bandeja, vende bandeja. Margen 50%.
A24: IZQUIERDA | B24: 24 | C24: Coliflor | D24: coliflor | E24: CONECTADO | F24: Coliflor | G24: 12ae5b8f-a359-4b3b-a373-d32cd67fb7fa | I24: DIRECTO_UNIDAD | J24: 50 | K24: UNIDAD | L24: UNIDAD | M24: Compra unidad, vende unidad. Margen 50%.
A25: IZQUIERDA | B25: 25 | C25: Curuba | D25: curuba | E25: CREAR_EN_APP | I25: SIN_REGLA | J25: 50 | K25: KILO | L25: KILO | M25: Sin regla específica. Revisar manualmente.
A26: IZQUIERDA | B26: 26 | C26: Champiñón | D26: champinon | E26: CREAR_EN_APP | I26: SIN_REGLA | J26: 50 | K26: KILO | L26: KILO | M26: Sin regla específica. Revisar manualmente.
A27: IZQUIERDA | B27: 27 | C27: Durazno | D27: durazno | E27: CONECTADO_CON_CORRECCION | F27: Durazno por Kilo | G27: b0a06757-960a-41e6-ab1d-1abf15786947 | I27: SIN_REGLA | J27: 50 | K27: KILO | L27: KILO | M27: Sin regla específica. Revisar manualmente.
A28: IZQUIERDA | B28: 28 | C28: Espinaca | D28: espinaca | E28: CONECTADO | F28: Espinaca | G28: 0e9b70bf-74be-4721-8d02-55dc197ef270 | I28: DIRECTO_KILO | J28: 100 | K28: KILO | L28: KILO | M28: Compra kilo, vende kilo. Margen 100%.
A29: IZQUIERDA | B29: 29 | C29: Fresa | D29: fresa | E29: CONECTADO_CON_CORRECCION | F29: Fresa Paquete | G29: a6aecb5c-24f1-4389-adbd-6be57f01d8f7 | I29: DIRECTO_BANDEJA | J29: 50 | K29: BANDEJA | L29: BANDEJA | M29: Compra caja/bandeja. Revisar presentación. Margen sugerido 50%.
A30: IZQUIERDA | B30: 30 | C30: Fresa Extra | D30: fresa_extra | E30: CREAR_EN_APP | I30: DIRECTO_BANDEJA | J30: 50 | K30: BANDEJA | L30: BANDEJA | M30: Compra caja/bandeja. Revisar presentación. Margen sugerido 50%.
A31: IZQUIERDA | B31: 31 | C31: Frijol Verde | D31: frijol_verde | E31: CREAR_EN_APP | I31: SIN_REGLA | J31: 50 | K31: KILO | L31: KILO | M31: Sin regla específica. Revisar manualmente.
A32: IZQUIERDA | B32: 32 | C32: Jengibre | D32: jengibre | E32: CONECTADO_CON_CORRECCION | F32: Gengibre | G32: 8f753906-dc41-463a-8ffc-aee040d5e716 | I32: DIRECTO_KILO | J32: 50 | K32: KILO | L32: KILO | M32: Compra kilo, vende kilo. Margen mínimo 50%.
A33: IZQUIERDA | B33: 33 | C33: Granadilla | D33: granadilla | E33: CONECTADO | F33: Granadilla | G33: a86be2c2-37e3-466a-90ae-8d4c563fa09e | I33: DIRECTO_UNIDAD | J33: 50 | K33: UNIDAD | L33: UNIDAD | M33: Compra unidad, vende unidad. Margen cercano 50%.
A34: IZQUIERDA | B34: 34 | C34: Guascas | D34: guascas | E34: CREAR_EN_APP | I34: SIN_REGLA | J34: 50 | K34: KILO | L34: KILO | M34: Sin regla específica. Revisar manualmente.
A35: IZQUIERDA | B35: 35 | C35: Guayaba | D35: guayaba | E35: CONECTADO | F35: Guayaba | G35: 54e187d2-e648-457e-9678-6b63f354c69a | I35: SIN_REGLA | J35: 50 | K35: KILO | L35: KILO | M35: Sin regla específica. Revisar manualmente.
A36: IZQUIERDA | B36: 36 | C36: Guayaba Pera | D36: guayaba_pera | E36: CREAR_EN_APP | I36: SIN_REGLA | J36: 50 | K36: KILO | L36: KILO | M36: Sin regla específica. Revisar manualmente.
A37: IZQUIERDA | B37: 37 | C37: Guatila | D37: guatila | E37: CREAR_EN_APP | I37: SIN_REGLA | J37: 50 | K37: KILO | L37: KILO | M37: Sin regla específica. Revisar manualmente.
A38: IZQUIERDA | B38: 38 | C38: Guanábana | D38: guanabana_fresca | E38: CREAR_FRUTA_FRESCA | F38: Guanábana (fruta fresca) | I38: SIN_REGLA | J38: 50 | K38: KILO | L38: KILO | M38: Sin regla específica. Revisar manualmente.
A39: IZQUIERDA | B39: 39 | C39: Habas | D39: habas | E39: CREAR_EN_APP | I39: SIN_REGLA | J39: 50 | K39: KILO | L39: KILO | M39: Sin regla específica. Revisar manualmente.
A40: IZQUIERDA | B40: 40 | C40: Habichuela | D40: habichuela | E40: CONECTADO | F40: Habichuela | G40: 50a105ae-2f87-4e4e-9045-5159cf593b60 | I40: DIRECTO_KILO | J40: 50 | K40: KILO | L40: KILO | M40: Compra kilo, vende kilo. Margen 50%.
...

Sheet REGLAS_PRECIOS
A1: productoClave | B1: productoReferencia | C1: tipoRegla | D1: margenObjetivo | E1: defaultConversion | F1: formula/resumen | G1: observacion
A2: acelga | B2: Acelga | C2: DIRECTO_KILO | D2: 60 | F2: Compra kilo, vende kilo. Margen mínimo 60%.
A3: aguacate | B3: Aguacate | C3: DIRECTO_KILO | D3: 45 | F3: Compra kilo, vende kilo. Margen recomendado 40-45%.
A4: ahuyamin | B4: Ahuyamín | C4: DIRECTO_KILO | D4: 35 | F4: Compra kilo, vende kilo. Margen 35%.
A5: aji_manual | B5: Ají | C5: MANUAL | D5: 60 | F5: Manejo manual. No actualizar automáticamente.
A6: ajo_criollo_manojo | B6: Ajo Criollo | C6: MATA_A_UNIDAD | D6: 45 | E6: 10 manojos/mata | F6: 1 mata = 10 manojos. Precio manojo = costo mata / 10 × 1,45.
A7: ajo_blanco_paquete | B7: Ajo Blanco | C7: KILO_A_PAQUETE_ESPECIAL | D7: 100 | E7: 21 paquetes/2 kg | F7: De 2 kg salen 21 paquetes de 3 cabezas. Precio = costo paquete × 2.
A8: ajo_pelado_base | B8: Ajo Pelado | C8: MULTI_FORMULA | D8: 45 | E8: 150g y 75g | F8: Kilo base: 150g margen 45%; 75g margen 60%.
A9: apio_espana | B9: Apio España | C9: MATA_A_KILO_ESPECIAL | D9: 70 | F9: Vender $3.000/kg si mata <= $3.970 y pesa mínimo 2,25kg; si no, costoKg × 1,70.
A10: arandanos | B10: Arándanos | C10: SIN_REGLA | D10: 50 | F10: Sin regla específica. Revisar manualmente.
A11: arveja_con_cascara | B11: Arveja | C11: MULTI_FORMULA | D11: 35 | F11: 3 kg con cáscara = 1 kg desgranada. Paquetes 150g y 270g según fórmula.
A12: arracacha | B12: Arracacha | C12: DIRECTO_KILO | D12: 35 | F12: Compra kilo, vende kilo. Margen 35%.
A13: banano | B13: Banano | C13: CAJA_A_KILO | D13: 40 | E13: 18,5 kg/caja | F13: Caja default 18,5 kg. Vende kilo.
A14: berenjena | B14: Berenjena | C14: SIN_REGLA | D14: 50 | F14: Sin regla específica. Revisar manualmente.
A15: brocoli | B15: Brócoli | C15: DIRECTO_UNIDAD | D15: 50 | F15: Compra unidad, vende unidad. Margen 50%.
A16: calabaza | B16: Calabaza | C16: SIN_REGLA | D16: 50 | F16: Sin regla específica. Revisar manualmente.
A17: calabacin | B17: Calabacín | C17: SIN_REGLA | D17: 50 | F17: Sin regla específica. Revisar manualmente.
A18: cebolla_cabezona_blanca | B18: Ceb. Cabezona Blanca | C18: BULTO_A_KILO | D18: 60 | E18: 50 kg/bulto | F18: Bulto default 50 kg o kilo. Margen recomendado 50-60%.
A19: cebolla_cabezona_roja | B19: Ceb. Cabezona Roja | C19: DIRECTO_KILO | D19: 35 | F19: Compra kilo, vende kilo. Margen 35%.
A20: cebolla_larga | B20: Ceb. Larga | C20: MATA_A_KILO | D20: 60 | E20: 25 kg/mata | F20: Mata default 25 kg. Vende kilo. Margen recomendado 50-60%.
A21: ceb_puerro | B21: Ceb. Puerro | C21: SIN_REGLA | D21: 50 | F21: Sin regla específica. Revisar manualmente.
A22: cilantro | B22: Cilantro | C22: MULTI_FORMULA | D22: 119 | E22: 65g/paquete | F22: Paquete 65g, precio base $1.000, objetivo 119%.
A23: ciruela | B23: Ciruela | C23: DIRECTO_BANDEJA | D23: 50 | F23: Compra bandeja, vende bandeja. Margen 50%.
A24: coliflor | B24: Coliflor | C24: DIRECTO_UNIDAD | D24: 50 | F24: Compra unidad, vende unidad. Margen 50%.
A25: curuba | B25: Curuba | C25: SIN_REGLA | D25: 50 | F25: Sin regla específica. Revisar manualmente.
A26: champinon | B26: Champiñón | C26: SIN_REGLA | D26: 50 | F26: Sin regla específica. Revisar manualmente.
A27: durazno | B27: Durazno | C27: SIN_REGLA | D27: 50 | F27: Sin regla específica. Revisar manualmente.
A28: espinaca | B28: Espinaca | C28: DIRECTO_KILO | D28: 100 | F28: Compra kilo, vende kilo. Margen 100%.
A29: fresa | B29: Fresa | C29: DIRECTO_BANDEJA | D29: 50 | F29: Compra caja/bandeja. Revisar presentación. Margen sugerido 50%.
A30: fresa_extra | B30: Fresa Extra | C30: DIRECTO_BANDEJA | D30: 50 | F30: Compra caja/bandeja. Revisar presentación. Margen sugerido 50%.
A31: frijol_verde | B31: Frijol Verde | C31: SIN_REGLA | D31: 50 | F31: Sin regla específica. Revisar manualmente.
A32: jengibre | B32: Jengibre | C32: DIRECTO_KILO | D32: 50 | F32: Compra kilo, vende kilo. Margen mínimo 50%.
A33: granadilla | B33: Granadilla | C33: DIRECTO_UNIDAD | D33: 50 | F33: Compra unidad, vende unidad. Margen cercano 50%.
A34: guascas | B34: Guascas | C34: SIN_REGLA | D34: 50 | F34: Sin regla específica. Revisar manualmente.
... A44: limon_taiti | B44: Limón Taití | C44: SIN_REGLA | D44: 50 | F44: Sin regla específica. Revisar manualmente.
A45: limon_castilla_docena | B45: Limón Castilla | C45: KILO_A_PAQUETE_GRAMOS | D45: 85 | E45: 360g/paquete 12 und | F45: Paquete 12 unidades = 360g. Precio = costoKg × 0,36 × 1,85.
A46: limon_mandarino | B46: Limón Mandarino | C46: DIRECTO_KILO | D46: 55 | F46: Compra kilo, vende kilo. Margen recomendado 55%.
A47: lulo_fresco | B47: Lulo | C47: CAJA_A_KILO | D47: 50 | E47: 11-12 kg/caja | F47: Fruta fresca. Caja default 11-12 kg. No conectar a pulpa.
A48: maiz_por_arroba | B48: Maíz por Arroba | C48: SIN_REGLA | D48: 50 | F48: Sin regla específica. Revisar manualmente.
A49: maiz_entero | B49: Maíz Entero | C49: SIN_REGLA | D49: 50 | F49: Sin regla específica. Revisar manualmente.
...

Sheet UNIDADES
A1: Codigo | B1: Normaliza como | C1: Uso
A2: KG | B2: KILO | C2: Kilos
A3: KL | B3: KILO | C3: Kilos
A4: KILO | B4: KILO | C4: Kilos
A5: UND | B5: UNIDAD | C5: Unidades
A6: UNIDAD | B6: UNIDAD | C6: Unidades
A7: CJ | B7: CAJA | C7: Caja completa
A8: CAJA | B8: CAJA | C8: Caja completa
A9: BT | B9: BULTO | C9: Bulto completo
A10: BULTO | B10: BULTO | C10: Bulto completo
A11: MTA | B11: MATA | C11: Mata completa
A12: MATA | B12: MATA | C12: Mata completa
... A17: ARROBA | B17: ARROBA | C17: Arroba

Sheet ALIAS
A1: Texto recibido / anterior | B1: Producto correcto | C1: productoClave | D1: Nota
A2: Aceiga | B2: Acelga | C2: acelga | D2: Corregir nombre en app cuando sea posible.
A3: Genjibre | B3: Jengibre | C3: jengibre | D3: Error ortográfico del formato anterior.
A4: Gengibre | B4: Jengibre | C4: jengibre | D4: Producto activo aparece así en la app.
A5: Uva Conbinada | B5: Uva Combinada | C5: uva_combinada | D5: Corregir nombre.
A6: Uva Isabela | B6: Uva Isabella | C6: uva_isabella | D6: Normalizar con doble l.
A7: Manzana Royal | B7: Manzana Royale | C7: manzana_royale | D7: Normalizar a Royale.
A8: Papa Gruesa | B8: Papa Pastusa | C8: papa_pastusa | D8: Son el mismo producto para la app.
A9: Tomate Chonto Grueso | B9: Tomate Chonto | C9: tomate_chonto | D9: Conectar al producto Tomate Chonto.
A10: Zanahoria Extra | B10: Zanahoria | C10: zanahoria | D10: No manejar calidades separadas.
A11: Zanahoria Cero | B11: Zanahoria | C11: zanahoria | D11: No manejar calidades separadas.
A12: Plátano | B12: Plátano Verde | C12: platano_verde | D12: También actualizar Plátano Maduro con mismo precio.
... A16: Tomate de Árbol | B16: Tomate de Árbol fresco | C16: tomate_arbol_fresco | D16: No conectar con pulpa.
